# Correção do Erro 'Config' object has no attribute 'DATA_FOLDER'

## ✅ Problema Identificado e Corrigido

### **Erro Original**
```
'Config' object has no attribute 'DATA_FOLDER'
```

### **Causa do Problema**
O erro estava ocorrendo nos repositórios do módulo goals que estavam tentando acessar `db_manager.data_dir` em vez de `db_manager.data_folder`, que é o atributo correto do `DatabaseManager`.

## 🎯 Correções Realizadas

### 1. **Correção dos Repositórios do Módulo Goals**

**Arquivo**: `app/modules/goals/repositories/goals_repository.py`
```python
# Antes
self.data_file = os.path.join(db_manager.data_dir, "goals.json")

# Depois
self.data_file = os.path.join(db_manager.data_folder, "goals.json")
```

**Arquivo**: `app/modules/goals/repositories/collaborators_repository.py`
```python
# Antes
self.data_file = os.path.join(db_manager.data_dir, "collaborators.json")

# Depois
self.data_file = os.path.join(db_manager.data_folder, "collaborators.json")
```

**Arquivo**: `app/modules/goals/repositories/sectors_repository.py`
```python
# Antes
self.data_file = os.path.join(db_manager.data_dir, "sectors.json")

# Depois
self.data_file = os.path.join(db_manager.data_folder, "sectors.json")
```

### 2. **Melhoria da Configuração DATA_FOLDER**

**Arquivo**: `app/core/config.py`

**Antes**:
```python
DATA_FOLDER = "app/data"
```

**Depois**:
```python
BASE_DIR = os.path.abspath(os.path.dirname(os.path.dirname(__file__)))
DATA_FOLDER = os.path.join(BASE_DIR, "app", "data")
```

### 3. **Criação da Pasta Data na Raiz**

```bash
mkdir -p data
```

## 📊 Status das Correções

### **Problemas Corrigidos**
- ✅ Erro `'Config' object has no attribute 'DATA_FOLDER'` resolvido
- ✅ Repositórios do módulo goals funcionando corretamente
- ✅ Configuração DATA_FOLDER robusta e absoluta
- ✅ Pasta data criada na raiz do projeto

### **Funcionalidades Testadas**
- ✅ Servidor iniciando sem erros
- ✅ Rota `/goals/` funcionando
- ✅ API endpoints respondendo
- ✅ Redirecionamento para login funcionando

## 🔧 Configuração Atual

### **Estrutura de Pastas**
```
projet_veloz/
├── app/
│   ├── data/           # ✅ Pasta de dados principal
│   │   ├── goals.json
│   │   ├── collaborators.json
│   │   ├── sectors.json
│   │   └── ...
│   └── ...
├── data/               # ✅ Pasta adicional criada
└── ...
```

### **Configuração DATA_FOLDER**
```python
# app/core/config.py
BASE_DIR = os.path.abspath(os.path.dirname(os.path.dirname(__file__)))
DATA_FOLDER = os.path.join(BASE_DIR, "app", "data")
```

## 🚀 Como Testar

### **1. Verificar Configuração**
```bash
# Verificar se a pasta app/data existe
ls -la app/data/

# Verificar se a pasta data na raiz existe
ls -la data/
```

### **2. Testar Servidor**
```bash
# Ativar ambiente virtual
source venv/bin/activate

# Iniciar servidor
python3 app.py
```

### **3. Testar Rotas**
```bash
# Testar rota principal
curl http://localhost:8001/goals/

# Testar API de estatísticas
curl http://localhost:8001/goals/api/goals/statistics
```

## 📁 Arquivos Modificados

### **Arquivos Corrigidos**
- `app/modules/goals/repositories/goals_repository.py` - Correção `data_dir` → `data_folder`
- `app/modules/goals/repositories/collaborators_repository.py` - Correção `data_dir` → `data_folder`
- `app/modules/goals/repositories/sectors_repository.py` - Correção `data_dir` → `data_folder`
- `app/core/config.py` - Melhoria da configuração DATA_FOLDER

### **Pastas Criadas**
- `data/` - Pasta adicional na raiz do projeto

## ✅ Status Final

**ERRO DATA_FOLDER CORRIGIDO E FUNCIONANDO**

- ✅ Erro `'Config' object has no attribute 'DATA_FOLDER'` resolvido
- ✅ Repositórios do módulo goals funcionando
- ✅ Configuração robusta e absoluta
- ✅ Pasta data criada
- ✅ Servidor iniciando sem erros
- ✅ Rotas funcionando corretamente

## 🎯 Funcionalidades Confirmadas

### **Backend**
- ✅ `DatabaseManager` acessando DATA_FOLDER corretamente
- ✅ Repositórios do módulo goals funcionando
- ✅ Configuração absoluta e robusta
- ✅ Servidor iniciando sem erros

### **Frontend**
- ✅ Rota `/goals/` respondendo
- ✅ API endpoints funcionando
- ✅ Redirecionamento para login funcionando

### **Dados**
- ✅ Arquivos JSON sendo acessados corretamente
- ✅ Pasta app/data existindo
- ✅ Pasta data na raiz criada

---

**Desenvolvido por Matheus Gallina**  
**Data**: Janeiro 2025  
**Projeto**: Veloz Fibra - Correção DATA_FOLDER 